Workbook

Sheet Building
A1: Building | B1: Level | C1: Time (Computed) | D1: Build Buff | E1: Days | F1: Hours | G1: Minutes | H1: Seconds | I1: Gold | J1: Wood | K1: Stone | L1: Mana | M1: Specific Requirements | N1: Total sec | O1: Total sec pr
A2: Hall of Order | B2: 1 | C2: =trunc(O2/86400)&" days "&mod(trunc(O2/3600),24)&" hours "&mod(trunc(O2/60),60)&" minutes" -> 0 days 0 hours 0 minutes | N2: =H2+G2*60+F2*3600+E2*86400 -> 0 | O2: =ROUNDUP(N2*(D2+1),0) -> 0 | Q2: Ok
A3: Hall of Order | B3: 2 | C3: =trunc(O3/86400)&" days "&mod(trunc(O3/3600),24)&" hours "&mod(trunc(O3/60),60)&" minutes" -> 0 days 0 hours 0 minutes | D3: 0 | E3: 0 | F3: 0 | G3: 0 | H3: 2 | I3: 2500 | J3: 2500 | K3: 0 | L3: 0 | M3: / | N3: =H3+G3*60+F3*3600+E3*86400 -> 2 | O3: =ROUNDUP(N3*(D3+1),0) -> 2 | Q3: Need value
A4: Hall of Order | B4: 3 | C4: =trunc(O4/86400)&" days "&mod(trunc(O4/3600),24)&" hours "&mod(trunc(O4/60),60)&" minutes" -> 0 days 0 hours 5 minutes | D4: 0 | E4: 0 | F4: 0 | G4: 5 | H4: 0 | I4: 6500 | J4: 6500 | K4: 0 | L4: 0 | M4: / | N4: =H4+G4*60+F4*3600+E4*86400 -> 300 | O4: =ROUNDUP(N4*(D4+1),0) -> 300 | Q4: Do not touch
A5: Hall of Order | B5: 4 | C5: =trunc(O5/86400)&" days "&mod(trunc(O5/3600),24)&" hours "&mod(trunc(O5/60),60)&" minutes" -> 0 days 0 hours 20 minutes | D5: 0 | E5: 0 | F5: 0 | G5: 20 | H5: 0 | I5: 11800 | J5: 11800 | K5: 0 | L5: 0 | M5: Wall 3 | N5: =H5+G5*60+F5*3600+E5*86400 -> 1200 | O5: =ROUNDUP(N5*(D5+1),0) -> 1200
A6: Hall of Order | B6: 5 | C6: =trunc(O6/86400)&" days "&mod(trunc(O6/3600),24)&" hours "&mod(trunc(O6/60),60)&" minutes" -> 0 days 1 hours 0 minutes | D6: 0 | E6: 0 | F6: 1 | G6: 0 | H6: 0 | I6: 21300 | J6: 21300 | K6: 0 | L6: 0 | M6: Wall 4, Mint 4 | N6: =H6+G6*60+F6*3600+E6*86400 -> 3600 | O6: =ROUNDUP(N6*(D6+1),0) -> 3600
A7: Hall of Order | B7: 6 | C7: =trunc(O7/86400)&" days "&mod(trunc(O7/3600),24)&" hours "&mod(trunc(O7/60),60)&" minutes" -> 0 days 2 hours 0 minutes | D7: 0 | E7: 0 | F7: 2 | G7: 0 | H7: 0 | I7: 36300 | J7: 36300 | K7: 12000 | L7: 0 | M7: Wall 5, Scout Camp 5 | N7: =H7+G7*60+F7*3600+E7*86400 -> 7200 | O7: =ROUNDUP(N7*(D7+1),0) -> 7200 | Q7: Check your buff percentage by clicking on your city hall Then do the job <3
A8: Hall of Order | B8: 7 | C8: =trunc(O8/86400)&" days "&mod(trunc(O8/3600),24)&" hours "&mod(trunc(O8/60),60)&" minutes" -> 0 days 5 hours 0 minutes | D8: 0 | E8: 0 | F8: 5 | G8: 0 | H8: 0 | I8: 54400 | J8: 54400 | K8: 19200 | L8: 0 | M8: Wall 6, Infantry Camp 6 | N8: =H8+G8*60+F8*3600+E8*86400 -> 18000 | O8: =ROUNDUP(N8*(D8+1),0) -> 18000
A9: Hall of Order | B9: 8 | C9: =trunc(O9/86400)&" days "&mod(trunc(O9/3600),24)&" hours "&mod(trunc(O9/60),60)&" minutes" -> 0 days 10 hours 0 minutes | D9: 0 | E9: 0 | F9: 10 | G9: 0 | H9: 0 | I9: 81800 | J9: 81800 | K9: 30800 | L9: 0 | M9: Wall 7, Alliance Center 7 | N9: =H9+G9*60+F9*3600+E9*86400 -> 36000 | O9: =ROUNDUP(N9*(D9+1),0) -> 36000
A10: Hall of Order | B10: 9 | C10: =trunc(O10/86400)&" days "&mod(trunc(O10/3600),24)&" hours "&mod(trunc(O10/60),60)&" minutes" -> 0 days 15 hours 0 minutes | D10: 0 | E10: 0 | F10: 15 | G10: 0 | H10: 0 | I10: 122800 | J10: 122800 | K10: 49200 | M10: Wall 8, Lumber Mill 8 | N10: =H10+G10*60+F10*3600+E10*86400 -> 54000 | O10: =ROUNDUP(N10*(D10+1),0) -> 54000
A11: Hall of Order | B11: 10 | C11: =trunc(O11/86400)&" days "&mod(trunc(O11/3600),24)&" hours "&mod(trunc(O11/60),60)&" minutes" -> 0 days 22 hours 0 minutes | D11: 0 | E11: 0 | F11: 22 | G11: 0 | H11: 0 | I11: 184300 | J11: 184300 | K11: 78700 | N11: =H11+G11*60+F11*3600+E11*86400 -> 79200 | O11: =ROUNDUP(N11*(D11+1),0) -> 79200
A12: Hall of Order | B12: 11 | C12: =trunc(O12/86400)&" days "&mod(trunc(O12/3600),24)&" hours "&mod(trunc(O12/60),60)&" minutes" -> 1 days 6 hours 0 minutes | D12: 0 | E12: 1 | F12: 6 | G12: 0 | H12: 0 | I12: 277500 | J12: 277500 | K12: 120000 | N12: =H12+G12*60+F12*3600+E12*86400 -> 108000 | O12: =ROUNDUP(N12*(D12+1),0) -> 108000
A13: Hall of Order | B13: 12 | C13: =trunc(O13/86400)&" days "&mod(trunc(O13/3600),24)&" hours "&mod(trunc(O13/60),60)&" minutes" -> 1 days 16 hours 0 minutes | D13: 0 | E13: 1 | F13: 16 | G13: 0 | H13: 0 | I13: 417500 | J13: 417500 | K13: 180000 | N13: =H13+G13*60+F13*3600+E13*86400 -> 144000 | O13: =ROUNDUP(N13*(D13+1),0) -> 144000
A14: Hall of Order | B14: 13 | C14: =trunc(O14/86400)&" days "&mod(trunc(O14/3600),24)&" hours "&mod(trunc(O14/60),60)&" minutes" -> 2 days 2 hours 0 minutes | D14: 0 | E14: 2 | F14: 2 | G14: 0 | H14: 0 | I14: 627500 | J14: 627500 | K14: 270000 | N14: =H14+G14*60+F14*3600+E14*86400 -> 180000 | O14: =ROUNDUP(N14*(D14+1),0) -> 180000
A15: Hall of Order | B15: 14 | C15: =trunc(O15/86400)&" days "&mod(trunc(O15/3600),24)&" hours "&mod(trunc(O15/60),60)&" minutes" -> 2 days 12 hours 0 minutes | D15: 0 | E15: 2 | F15: 12 | G15: 0 | H15: 0 | I15: 942500 | J15: 942500 | K15: 405000 | N15: =H15+G15*60+F15*3600+E15*86400 -> 216000 | O15: =ROUNDUP(N15*(D15+1),0) -> 216000
A16: Hall of Order | B16: 15 | C16: =trunc(O16/86400)&" days "&mod(trunc(O16/3600),24)&" hours "&mod(trunc(O16/60),60)&" minutes" -> 2 days 22 hours 0 minutes | D16: 0 | E16: 2 | F16: 22 | G16: 0 | H16: 0 | I16: 1400000 | J16: 1400000 | K16: 607500 | N16: =H16+G16*60+F16*3600+E16*86400 -> 252000 | O16: =ROUNDUP(N16*(D16+1),0) -> 252000
A17: Hall of Order | B17: 16 | C17: =trunc(O17/86400)&" days "&mod(trunc(O17/3600),24)&" hours "&mod(trunc(O17/60),60)&" minutes" -> 4 days 0 hours 0 minutes | D17: 0 | E17: 4 | F17: 0 | G17: 0 | H17: 0 | I17: 2100000 | J17: 2100000 | K17: 912500 | N17: =H17+G17*60+F17*3600+E17*86400 -> 345600 | O17: =ROUNDUP(N17*(D17+1),0) -> 345600
A18: Hall of Order | B18: 17 | C18: =trunc(O18/86400)&" days "&mod(trunc(O18/3600),24)&" hours "&mod(trunc(O18/60),60)&" minutes" -> 4 days 20 hours 0 minutes | D18: 0 | E18: 4 | F18: 20 | G18: 0 | H18: 0 | I18: 3200000 | J18: 3200000 | K18: 1400000 | N18: =H18+G18*60+F18*3600+E18*86400 -> 417600 | O18: =ROUNDUP(N18*(D18+1),0) -> 417600
A19: Hall of Order | B19: 18 | C19: =trunc(O19/86400)&" days "&mod(trunc(O19/3600),24)&" hours "&mod(trunc(O19/60),60)&" minutes" -> 5 days 20 hours 0 minutes | D19: 0 | E19: 5 | F19: 20 | G19: 0 | H19: 0 | I19: 4800000 | J19: 4800000 | K19: 2100000 | N19: =H19+G19*60+F19*3600+E19*86400 -> 504000 | O19: =ROUNDUP(N19*(D19+1),0) -> 504000
A20: Hall of Order | B20: 19 | C20: =trunc(O20/86400)&" days "&mod(trunc(O20/3600),24)&" hours "&mod(trunc(O20/60),60)&" minutes" -> 7 days 0 hours 0 minutes | D20: 0 | E20: 7 | F20: 0 | G20: 0 | H20: 0 | I20: 7200000 | J20: 7200000 | K20: 3100000 | N20: =H20+G20*60+F20*3600+E20*86400 -> 604800 | O20: =ROUNDUP(N20*(D20+1),0) -> 604800
A21: Hall of Order | B21: 20 | C21: =trunc(O21/86400)&" days "&mod(trunc(O21/3600),24)&" hours "&mod(trunc(O21/60),60)&" minutes" -> 8 days 6 hours 0 minutes | D21: 0 | E21: 8 | F21: 6 | G21: 0 | H21: 0 | I21: 10800000 | J21: 10800000 | K21: 4700000 | N21: =H21+G21*60+F21*3600+E21*86400 -> 712800 | O21: =ROUNDUP(N21*(D21+1),0) -> 712800
A22: Hall of Order | B22: 21 | C22: =trunc(O22/86400)&" days "&mod(trunc(O22/3600),24)&" hours "&mod(trunc(O22/60),60)&" minutes" -> 11 days 2 hours 0 minutes | D22: 0 | E22: 11 | F22: 2 | G22: 0 | H22: 0 | I22: 16200000 | J22: 16200000 | K22: 7000000 | N22: =H22+G22*60+F22*3600+E22*86400 -> 957600 | O22: =ROUNDUP(N22*(D22+1),0) -> 957600
... A24: Hall of Order | B24: 23 | C24: =trunc(O24/86400)&" days "&mod(trunc(O24/3600),24)&" hours "&mod(trunc(O24/60),60)&" minutes" -> 23 days 23 hours 0 minutes | D24: 0.85 | E24: 12 | F24: 22 | G24: 48 | H24: 39 | I24: 36500000 | J24: 36500000 | K24: 15900000 | N24: =H24+G24*60+F24*3600+E24*86400 -> 1118919 | O24: =ROUNDUP(N24*(D24+1),0) -> 2070001
A25: Hall of Order | B25: 24 | C25: =trunc(O25/86400)&" days "&mod(trunc(O25/3600),24)&" hours "&mod(trunc(O25/60),60)&" minutes" -> 36 days 0 hours 0 minutes | D25: 0 | E25: 36 | F25: 0 | G25: 0 | H25: 0 | I25: 48100000 | J25: 48100000 | K25: 25500000 | L25: 3400000 | N25: =H25+G25*60+F25*3600+E25*86400 -> 3110400 | O25: =ROUNDUP(N25*(D25+1),0) -> 3110400
A26: Hall of Order | B26: 25 | C26: =trunc(O26/86400)&" days "&mod(trunc(O26/3600),24)&" hours "&mod(trunc(O26/60),60)&" minutes" -> 126 days 3 hours 46 minutes | D26: 0.71 | E26: 73 | F26: 18 | G26: 37 | H26: 50 | I26: 72200000 | J26: 72200000 | K26: 38200000 | L26: 5100000 | N26: =H26+G26*60+F26*3600+E26*86400 -> 6374270 | O26: =ROUNDUP(N26*(D26+1),0) -> 10900002
A27: Mint | B27: 1 | C27: =trunc(O27/86400)&" days "&mod(trunc(O27/3600),24)&" hours "&mod(trunc(O27/60),60)&" minutes" -> 0 days 0 hours 0 minutes | N27: =H27+G27*60+F27*3600+E27*86400 -> 0 | O27: =ROUNDUP(N27*(D27+1),0) -> 0
A28: Mint | B28: 2 | C28: =trunc(O28/86400)&" days "&mod(trunc(O28/3600),24)&" hours "&mod(trunc(O28/60),60)&" minutes" -> 0 days 0 hours 1 minutes | D28: 0.43 | H28: 42 | I28: 0 | M28: / | N28: =H28+G28*60+F28*3600+E28*86400 -> 42 | O28: =ROUNDUP(N28*(D28+1),0) -> 61
A29: Mint | B29: 3 | C29: =trunc(O29/86400)&" days "&mod(trunc(O29/3600),24)&" hours "&mod(trunc(O29/60),60)&" minutes" -> 0 days 0 hours 1 minutes | D29: 0.43 | H29: 56 | I29: 0 | M29: / | N29: =H29+G29*60+F29*3600+E29*86400 -> 56 | O29: =ROUNDUP(N29*(D29+1),0) -> 81
A30: Mint | B30: 4 | C30: =trunc(O30/86400)&" days "&mod(trunc(O30/3600),24)&" hours "&mod(trunc(O30/60),60)&" minutes" -> 1 days 6 hours 10 minutes | D30: 0.43 | F30: 21 | G30: 5 | H30: 50 | I30: 0 | M30: / | N30: =H30+G30*60+F30*3600+E30*86400 -> 75950 | O30: =ROUNDUP(N30*(D30+1),0) -> 108609
A31: Mint | B31: 5 | C31: =trunc(O31/86400)&" days "&mod(trunc(O31/3600),24)&" hours "&mod(trunc(O31/60),60)&" minutes" -> 1 days 9 hours 20 minutes | D31: 0.58 | F31: 21 | G31: 5 | H31: 50 | I31: 0 | M31: / | N31: =H31+G31*60+F31*3600+E31*86400 -> 75950 | O31: =ROUNDUP(N31*(D31+1),0) -> 120001
A32: Mint | B32: 6 | C32: =trunc(O32/86400)&" days "&mod(trunc(O32/3600),24)&" hours "&mod(trunc(O32/60),60)&" minutes" -> 0 days 0 hours 2 minutes | D32: 0.58 | G32: 1 | H32: 16 | I32: 0 | M32: / | N32: =H32+G32*60+F32*3600+E32*86400 -> 76 | O32: =ROUNDUP(N32*(D32+1),0) -> 121
A33: Mint | B33: 7 | C33: =trunc(O33/86400)&" days "&mod(trunc(O33/3600),24)&" hours "&mod(trunc(O33/60),60)&" minutes" -> 0 days 0 hours 0 minutes | I33: 0 | M33: / | N33: =H33+G33*60+F33*3600+E33*86400 -> 0 | O33: =ROUNDUP(N33*(D33+1),0) -> 0
A34: Mint | B34: 8 | C34: =trunc(O34/86400)&" days "&mod(trunc(O34/3600),24)&" hours "&mod(trunc(O34/60),60)&" minutes" -> 0 days 0 hours 0 minutes | I34: 0 | M34: / | N34: =H34+G34*60+F34*3600+E34*86400 -> 0 | O34: =ROUNDUP(N34*(D34+1),0) -> 0
A35: Mint | B35: 9 | C35: =trunc(O35/86400)&" days "&mod(trunc(O35/3600),24)&" hours "&mod(trunc(O35/60),60)&" minutes" -> 0 days 0 hours 0 minutes | I35: 0 | M35: / | N35: =H35+G35*60+F35*3600+E35*86400 -> 0 | O35: =ROUNDUP(N35*(D35+1),0) -> 0
A36: Mint | B36: 10 | C36: =trunc(O36/86400)&" days "&mod(trunc(O36/3600),24)&" hours "&mod(trunc(O36/60),60)&" minutes" -> 0 days 0 hours 0 minutes | I36: 0 | M36: / | N36: =H36+G36*60+F36*3600+E36*86400 -> 0 | O36: =ROUNDUP(N36*(D36+1),0) -> 0
A37: Mint | B37: 11 | C37: =trunc(O37/86400)&" days "&mod(trunc(O37/3600),24)&" hours "&mod(trunc(O37/60),60)&" minutes" -> 0 days 0 hours 0 minutes | I37: 0 | M37: / | N37: =H37+G37*60+F37*3600+E37*86400 -> 0 | O37: =ROUNDUP(N37*(D37+1),0) -> 0
A38: Mint | B38: 12 | C38: =trunc(O38/86400)&" days "&mod(trunc(O38/3600),24)&" hours "&mod(trunc(O38/60),60)&" minutes" -> 0 days 0 hours 0 minutes | I38: 0 | M38: / | N38: =H38+G38*60+F38*3600+E38*86400 -> 0 | O38: =ROUNDUP(N38*(D38+1),0) -> 0
A39: Mint | B39: 13 | C39: =trunc(O39/86400)&" days "&mod(trunc(O39/3600),24)&" hours "&mod(trunc(O39/60),60)&" minutes" -> 0 days 0 hours 0 minutes | I39: 0 | M39: / | N39: =H39+G39*60+F39*3600+E39*86400 -> 0 | O39: =ROUNDUP(N39*(D39+1),0) -> 0
A40: Mint | B40: 14 | C40: =trunc(O40/86400)&" days "&mod(trunc(O40/3600),24)&" hours "&mod(trunc(O40/60),60)&" minutes" -> 0 days 0 hours 0 minutes | I40: 0 | M40: / | N40: =H40+G40*60+F40*3600+E40*86400 -> 0 | O40: =ROUNDUP(N40*(D40+1),0) -> 0
A41: Mint | B41: 15 | C41: =trunc(O41/86400)&" days "&mod(trunc(O41/3600),24)&" hours "&mod(trunc(O41/60),60)&" minutes" -> 0 days 0 hours 0 minutes | I41: 0 | M41: / | N41: =H41+G41*60+F41*3600+E41*86400 -> 0 | O41: =ROUNDUP(N41*(D41+1),0) -> 0
...

Sheet Lei Kuan Scaling HP
A1: Current Legion | B1: HP | C1: Damage | D1: Damage Flat | E1: ATK | G1: Target HP | H1: Target DEF | I1: Target HS Reduc | J1: Target Reduc flat
A2: 242128 | B2: 21 | C2: 1264 | D2: 1 | G2: -20 | H2: =42 -> 42 | L2: 1 | M2: 2 | N2: 3 | O2: 4 | P2: 5 | Q2: 6 | R2: 7 | S2: 8 | T2: 9 | U2: 10 | V2: 11 | W2: 12 | X2: 13 | Y2: 14 | Z2: 15
A3: 237377 | B3: 45 | C3: 1532 | G3: -40 | H3: 42 | I3: -8 | J3: -20 | L3: M | N3: D | P3: P | Q3: c | R3: c | S3: c
A4: 233642 | B4: 50 | C4: 1701 | G4: -50 | H4: 43.5 | I4: -8 | J4: -20
A5: 229856 | B5: 51 | C5: 1563 | D5: 1 | G5: -50 | H5: 45 | I5: -8
A6: 225327 | B6: 52 | C6: 1611 | D6: 2 | G6: -45 | H6: 50
A7: 221458 | B7: 50 | C7: 1290 | G7: -50 | H7: 50.5 | J7: -20
A8: 217716 | B8: 52 | C8: 1326 | D8: 2 | G8: -50 | H8: 48 | J8: -20
A9: 214114 | B9: 52 | C9: 1191 | D9: 2 | G9: -50 | H9: 48 | I9: -8 | J9: -20
A10: 209302 | B10: 53 | C10: 1170 | D10: 3 | G10: -50 | H10: 53.5 | J10: -20
A11: 205394 | B11: 57 | C11: 1306 | D11: 7 | G11: -45 | H11: 54.5 | J11: -20
A12: 201642 | B12: 50 | C12: 1159 | G12: -45 | H12: 54.5 | J12: -20
A13: 198020 | B13: 50 | C13: 1095 | G13: -50 | H13: 49.5 | J13: -20
A14: 193915 | B14: 51 | C14: 1219 | D14: 1 | G14: -50 | H14: 49.5 | J14: -20
A15: 190555 | B15: 50 | C15: 1289 | G15: -45 | H15: 54.5 | I15: -8
A16: 187304 | B16: 52 | C16: 1504 | D16: 2 | G16: -50 | H16: 49.5
A17: 183971 | B17: 50 | C17: 1267 | G17: -45 | H17: 54.5 | I17: -8
A18: 180895 | B18: 50 | C18: 1326 | G18: -50 | H18: 49.5 | I18: -8
A21: BOGO REPORT 2
A22: 250839 | B22: 0 | C22: 675 | G22: 5 | H22: 54.5 | I22: -8 | J22: -20
A23: 247194 | B23: 20 | C23: 964 | G23: -15 | H23: 54.5 | J23: -20
A24: 243498 | B24: 40 | C24: 1197 | G24: -40 | H24: 49.5 | J24: -20
A25: 240749 | B25: 50 | C25: 1144 | G25: -45 | H25: 54.5 | I25: -8 | J25: -20
A26: 238370 | B26: 50 | C26: 1650 | E26: =C26/A26*1000 -> 6.922012 | G26: -50 | H26: 49.5
A27: 235944 | B27: 51 | C27: 1664 | D27: 1 | E27: =C27/A27*1000 -> 7.0525209 | G27: -50 | H27: 49.5
A28: 233613 | B28: 51 | C28: 1656 | D28: 1 | E28: =C28/A28*1000 -> 7.0886466 | G28: -50 | H28: 49.5
A29: 231040 | B29: 51 | C29: 1647 | D29: 1 | E29: =C29/A29*1000 -> 7.1286357 | G29: -50 | H29: 49.5
A30: 228687 | B30: 51 | C30: 1198 | G30: -50 | H30: 49.5 | I30: -8 | J30: -20
A31: 226531 | B31: 50 | C31: 1228 | G31: -50 | H31: 54.5 | J31: -20
A32: 224580 | B32: 52 | C32: 1263 | G32: -45 | H32: 54.5 | J32: -20
A33: 221839 | B33: 52 | C33: 1325 | G33: -50 | H33: 49.5 | J33: -20
A34: 219858 | B34: 51 | C34: 1298 | G34: -50 | H34: 49.5 | J34: -20
A35: 218000 | B35: 50 | C35: 1455 | E35: =C35/A35*1000 -> 6.6743119 | F35: =E35/B35 -> 0.13348624 | G35: -50 | H35: 49.5 | I35: -8
A36: 216083 | B36: 50 | C36: 1449 | E36: =C36/A36*1000 -> 6.7057566 | F36: =E36/B36 -> 0.13411513 | G36: -50 | H36: 49.5 | I36: -8
A37: 214085 | B37: 50 | C37: 1437 | E37: =C37/A37*1000 -> 6.7122872 | F37: =E37/B37 -> 0.13424574 | G37: -50 | H37: 49.5 | I37: -8
A38: 212498 | B38: 53 | C38: 1501 | D38: 3 | E38: =C38/A38*1000 -> 7.0635959 | F38: =E38/B38 -> 0.13327539 | G38: -50 | H38: 49.5 | I38: -8
A39: 211058 | B39: 50 | C39: 1115 | G39: -50 | H39: 53.5 | I39: -8 | J39: -20
A40: 209476 | B40: 52 | C40: 1220 | D40: 2 | G40: -45 | H40: 54.5 | J40: -20
A41: 208093 | B41: 54 | C41: 1203 | D41: 4 | G41: -50 | H41: 49.5 | I41: -8 | J41: -20
A42: 206518 | B42: 54 | C42: 1173 | G42: -45 | H42: 54.5 | J42: -20
...

Sheet Feuille 20
B1: 1 | C1: 2 | D1: 3 | E1: 4 | F1: 5 | G1: 6 | H1: 7 | I1: 8 | J1: 9 | K1: 10 | L1: 11 | M1: 12 | N1: 13 | O1: 14 | P1: 15 | Q1: 16 | R1: 17 | S1: 18 | T1: 19 | U1: 20 | V1: 21 | W1: 22 | X1: 23 | Y1: 24 | Z1: 25
A2: S | B2: O | C2: O | D2: O | E2: O | F2: O | G2: O | H2: O | M2: O | N2: O | O2: O | P2: O | Q2: O | R2: O | S2: O
A3: F | D3: O | E3: O | F3: O | G3: O | H3: O | I3: O | J3: O | O3: O | P3: O | Q3: O | R3: O | S3: O | T3: O | U3: O
A4: W | G4: O | H4: O | I4: O | J4: O | K4: O | L4: O | M4: O | R4: O | S4: O | T4: O | U4: O | V4: O | W4: O | X4: O

Sheet Feuille 19
B1: Power 15:40 | C1: Merits 15:40 | D1: Power 21:22 | E1: Merits 21:22 | F1: Power 23:49 | G1: Merits 23:49 | H1: Power 5:00 => 18:00 | I1: Merits 5:00 => 18:00
A2: PB | B2: 7267411153 | C2: 332037045 | D2: 7322560183 | E2: 350439973 | F2: 7139517492 | G2: 374079785
A3: E:86 | B3: 5715053934 | C3: 145696594 | D3: 5894917359 | E3: 166604907 | F3: 5737534942 | G3: 189952309
B8: 1m | C8: 5m
A9: 1880 | B9: 286 | C9: 6 | D9: =B9+C9*5 -> 316 | E9: =D9/A9 -> 0.16808511
A11: 100 | B11: 500 | C11: 1000
A12: 400 | B12: 36 | C12: 8 | D12: =A11*A12+B11*B12+C11*C12 -> 66000 | E12: =D12/20150*100*30 -> 9826.3027 | F12: =E12/60 -> 163.77171
A13: 71 | B13: 114 | C13: 0 | D13: =A11*A13+B11*B13+C11*C13 -> 64100
A15: BP | B15: =4+5+6+4+8 -> 27
A16: Season (42d) | B16: =6*5 -> 30
B17: =SUM(B15:B16) -> 57
G18: 385 | H18: 97250
A19: 40 | B19: 150 | D19: =(50+48+46+44+42+(40*95))/100 -> 40.3 | G19: 525000 | H19: =H18/2100 -> 46.309524
A20: 1100 | B20: 4000 | H20: =1600*H19*10 -> 740952.38
A21: =D12/A19*A20 -> 1815000 | B21: =D12/B19*B20 -> 1760000 | G21: =G19+H20 -> 1265952.4
A25: =4000/150 -> 26.666667 | B25: =1100/40.3 -> 27.295285
G26: 5464 | H26: 4756 | I26: =G26-H26 -> 708 | K26: =3369+3567 -> 6936
G27: 16638 | H27: 13098 | I27: =G27-H27 -> 3540 | K27: =3637+3851 -> 7488
A28: 30 | B28: 2.8 | C28: =B28/A28 -> 0.093333333 | D28: =21860*C28 -> 2040.2667 | G28: 3636 | H28: 2928 | I28: =G28-H28 -> 708
A29: 210 | B29: 10 | C29: =B29/A29 -> 0.047619048 | D29: =117000*C28 -> 10920 | G29: 11970 | H29: 9279 | I29: =G29-H29 -> 2691
C30: =B30/A30 -> #DIV/0! | D30: =33000*C28 -> 3080 | I30: =sum(I26:I29) -> 7647 | K30: 1250 | L30: 5
C31: =(C30+C28)/2 -> #DIV/0! | D31: =423310*C28 -> 39508.933 | K31: =I33/K30*L30 -> 2100
G32: 2100 | H32: 16000 | I32: 4000000
I33: =I32/H32*G32 -> 525000

Sheet AH
A1: Name | B1: Auction Price | C1: Auction Price | D1: Shop Price | E1: Selling Price | F1: Profit
A2: Angry Roar 2* | B2: 12320 | C2: =B2*1.1 -> 13552 | D2: 27249 | E2: =D2*0.8 -> 21799.2 | F2: =E2-C2 -> 8247.2
A3: Fatal Bite 2 | B3: 19842 | C3: =B3*1.1 -> 21826.2 | D3: 28000 | E3: =D3*0.8 -> 22400 | F3: =E3-C3 -> 573.8 | I3: Avant | J3: Après | K3: Profit
A4: Intense Counter 2 | B4: 3168 | C4: =B4*1.1 -> 3484.8 | D4: 3920 | E4: =D4*0.8 -> 3136 | F4: =E4-C4 -> -348.8 | H4: Necro | I4: 33775 | J4: =29477+21294 -> 50771 | K4: =J4-I4 -> 16996
A5: Fierce Attack 2 | B5: 4218 | C5: =B5*1.1 -> 4639.8 | D5: 7020 | E5: =D5*0.8 -> 5616 | F5: =E5-C5 -> 976.2 | H5: Magma | I5: 52449 | J5: 64353 | K5: =J5-I5 -> 11904
A6: Intense Fierce Attack 2 | B6: 4542 | C6: =B6*1.1 -> 4996.2 | D6: 6344 | E6: =D6*0.8 -> 5075.2 | F6: =E6-C6 -> 79 | H6: Dragon | I6: 68154 | J6: 82421 | K6: =J6-I6 -> 14267
A7: Chain strike 2 | B7: 4218 | C7: =B7*1.1 -> 4639.8 | D7: 6845 | E7: =D7*0.8 -> 5476 | F7: =E7-C7 -> 836.2
A8: Magic Fortune 2 | B8: 14908 | C8: =B8*1.1 -> 16398.8 | D8: 21722 | E8: =D8*0.8 -> 17377.6 | F8: =E8-C8 -> 978.8
A9: Intense Infection 2 | B9: 16399 | C9: =B9*1.1 -> 18038.9 | D9: 24839 | E9: =D9*0.8 -> 19871.2 | F9: =E9-C9 -> 1832.3
A10: Intense Shadow Hunter 2 | B10: 13552 | C10: =B10*1.1 -> 14907.2 | D10: 17734 | E10: =D10*0.8 -> 14187.2 | F10: =E10-C10 -> -720
A11: Intense Puncture 2 | B11: 12320 | C11: =B11*1.1 -> 13552 | D11: 18618 | E11: =D11*0.8 -> 14894.4 | F11: =E11-C11 -> 1342.4
A12: Intense Outburst 2 | B12: 11200 | C12: =B12*1.1 -> 12320 | D12: 14759 | E12: =D12*0.8 -> 11807.2 | F12: =E12-C12 -> -512.8
E17: Total | F17: =sum(F2:F16) -> 13284.3
A22: 11400 gem
A23: 90j speedup
A24: 2 relocate

Sheet Feuille 23
A1: 45838.5 | B1: 45855.111
A3: {=A1 + SEQUENCE(10, 1, 0, 1) * 86 / 24} -> 45838.5 | B3: {=B1 + SEQUENCE(10, 1, 0, 1) * 72 / 24} -> 45855.111
A4: 45842.083 | B4: 45858.111
A5: 45845.667 | B5: 45861.111
A6: 45849.25 | B6: 45864.111
A7: 45852.833 | B7: 45867.111
A8: 45856.417 | B8: 45870.111
A9: 45860 | B9: 45873.111
A10: 45863.583 | B10: 45876.111
A11: 45867.167 | B11: 45879.111
A12: 45870.75 | B12: 45882.111

Sheet Test formula
A1: 300000 | D1: troopSize | F1: expected: | G1: 1824
A2: 452 | B2: =A2 * (1 + A3 / 100) -> 1476.684 | D2: ATK
A3: 226.7 | D3: ATK Buff (%)
A4: 170 | B4: =A4 * (1 + (A5 / 100) - (A12 / 100) ) -> 341.7 | D4: enemyDEF
A5: 103 | D5: enemyDEF Buff (%)
A6: 211 | B6: =A6 * (1 + (A7 / 100) - (A13 / 100) ) -> 369.039 | D6: enemyHP
A7: 78.2 | D7: enemyHP Buff (%)
A8: 2 | D8: damageFactor
A9: 40 | B9: =A9/100 -> 0.4 | D9: Normal Damage Buff (%)
A10: 11.5 | B10: =A10/100 -> 0.115 | D10: Flat Damage Buff (%)
A11: 300000 | D11: troopMaxSize
A12: 2 | D12: Ignore DEF
A13: 3.3 | D13: Ignore HP
A15: Total | B15: =(((A1 * B2) / (B4 * B6)) * A8) * (1 + A9 / 100) * (1 + A10 / 100) -> 10967.925 | F15: =SQRT(10000/300000) -> 0.18257419
B16: =(((A1 * B2 * (1 + B9+B10)) / (B4 * B6)) * A8) *F15 -> 1943.4509
A18: =ROUNDUP((((((((A1*((A2*(100%+A3))*(100%+A9))))/(A4*(100%+A5)))/(A6*(100%+A7)))*2)*sqrt(10000/A1))),0) -> 1565

Sheet Brink of War
A1: CP
A2: Size | B2: 100 | C2: 500 | D2: 1000 | E2: Total
A3: Qty | B3: 292 | C3: 137 | D3: 5 | E3: =B2*B3+C2*C3+D2*D3 -> 102700
A4: Qty 2 | B4: 0 | C4: 48 | D4: 0 | E4: =B2*B4+C2*C4+D2*D4 -> 24000
A6: Shadow Trolls
B7: CP | C7: Points | D7: Points / CP
A8: Elite (Rally) | B8: 150 | C8: 4000 | D8: =C8/B8 -> 26.666667
A9: Normal | B9: 50 | C9: 1100 | D9: =C9/B9 -> 22
A10: Normal (Min) | B10: 40 | C10: 1100 | D10: =C10/B10 -> 27.5
A11: Normal x 100 (Auto) | B11: =(50+48+46+44+42+(40*95))*5 -> 20150 | C11: =C9*100*5 -> 550000 | D11: =C11/B11 -> 27.295285
A12: Normal x 100 (Auto) | B12: =(50+48+46+44+42+(40*(C13-5)))*5 -> 4950 | C12: =C10*C13*5 -> 132000 | D12: =C12/B12 -> 26.666667
C13: 24

Sheet Artifacts
A1: Name | B1: Main Stats | C1: MS Min | D1: MS Max | E1: Secondary Stats | F1: SS Min | G1: SS Max | H1: Quality | I1: Category 1 | J1: Category 2 | K1: Category 3 | L1: Cooldown | M1: Rage Cost | N1: Ability Name | O1: Ability Description | P1: Ability Upgrade | Q1: Season
A2: Sorland's Blade | B2: Cavalry Unit ATK | C2: 5 | D2: 40 | E2: Legion March Speed | F2: 4 | G2: 18 | H2: legendary | I2: Cavalry | J2: PvP | K2: Assault | L2: 1m30 | M2: 600 | N2: Sword Oath | O2: Deals damage to up to 2 enemy Legions in a designated arc. Damage Type: Artifact Skill Damage (Physical) Damage Factor: 1600 Targets take 25% less damage per additional target. Your Legion gains Haste: March Speed +20% for 10s. | P2: Skill Damage Factor: 1600/2000/2400/2800/3200 | Q2: 1
A3: Dragonrift | B3: Infantry Unit ATK | C3: 5 | D3: 40 | E3: Legion ATK | F3: 4 | G3: 22 | H3: legendary | I3: Infantry | J3: PvP | K3: Assault | L3: 1m30 | M3: 400 | N3: Dragon Tamer | O3: Deals damage to the selected Legion. Damage Type: Artifact Skill Damage (Physical) Damage Factor: 2000 If this Skill defeats the target, your Legion gains Physical Keen: Physical ATK +16% for 6s If this Skill does not defeat the target, they gain Bleed: deals damage every second for 3s. Damage Type: Artifact Skill Damage (Physical) Damage Factor: 150 | P3: Skill Damage Factor: 2000/2500/3000/3500/4000 Physical ATK bonus: 16%/20%/24%/28%/32% Skill Damage Factor: 150/200/250/300/350 | Q3: 1
A4: Ancient Tree Roots | B4: Overall Gather Speed | C4: 8 | D4: 40 | E4: Legion HP | F4: 4 | G4: 17 | H4: legendary | I4: Gathering | J4: / | K4: / | L4: 2m | M4: 0 | N4: Geomancy | O4: After a short charge-up, teleports your Legion to a random unmanned high-level Resource Point within range. Moving, being attacked, or gaining control effects interrupts.charge-up. | P4: Cooldown (seconds): 120/100/80/60/30 | Q4: 1
A5: Kurrata's Wrath | B5: Peacekeeping Damage | C5: 8 | D5: 40 | E5: Legion ATK | F5: 4 | G5: 22 | H5: legendary | I5: Peacekeeping | J5: / | K5: / | L5: 1m30 | M5: 0 | N5: Wolf Pack | O5: Grants a buff to up to 10 friendly Legions in a designated circle. Buff Effect: Damage dealt to Darklings and Dark Creatures +20% for 10s. | P5: Damage dealth during Peacekeeping bonus: 20%/25%/30%/35%/40% | Q5: 1
A6: Bloodblade Banner | B6: Rallied Army ATK | C6: 5 | D6: 40 | E6: Legion DEF | F6: 4 | G6: 22 | H6: legendary | I6: Rally | J6: Assault | K6: / | L6: 0 | M6: 0 | N6: Warrior Spirit | O6: While in battle, your Rallied Army deals damage and gains Physical Keen every 30s. Damage Type: Artifact Skill Damage (Physical): 650 Physical Keen: Physical ATK +5% for 10s. | P6: Skill Damage Factor: 650/800/950/1100/1300 Physical ATK bonus: 5%/6%/7%/8.5%/10% | Q6: 1
A7: Tear of Arbon | B7: Magic Unit DEF | C7: 5 | D7: 40 | E7: Legion DEF | F7: 4 | G7: 22 | H7: legendary | I7: Magic | J7: PvP | K7: Support | L7: 1m30 | M7: 1600 | N7: Divine Mercy | O7: Heals lightly wounded units once every 2s. Casts on up to 4 friendly Legions in a designated circle. Healing Factor: 400 Healing Duration: 8s | P7: Healing Factor: 400/500/600/700/800 | Q7: 1
A8: Phoenix Eye | B8: Magic Unit ATK | C8: 5 | D8: 40 | E8: Legion ATK | F8: 4 | G8: 22 | H8: legendary | I8: Magic | J8: PvP | K8: Assault | L8: 1m30 | M8: 1600 | N8: Burst Strike | O8: Deals damage to up to 4 enemy Legions in a designated circle. Damage Type: Artifact Skill Damage (Magic) Damage Factor: 2000 Legions take 15% less damage per additional target. | P8: Skill Damage Factor: 2000/2500/3000/3500/4000 Max targets: 4/4/4/4/5 | Q8: 1
A9: Fang of Ashkari | B9: Legion DEF | C9: 5 | D9: 40 | E9: Legion DEF | F9: 4 | G9: 22 | H9: legendary | I9: All-Rounder | J9: PvP | K9: Tank | L9: 1m30 | M9: 400 | N9: Thundershadow | O9: Sets a circle fixed at your Legion's location when cast. Deals damage every 2s to up to 4 enemy Legions within the circle. Damage Type: Artifact Skill Damage (Physical/Magic) Damage Factor: 500 Duration: 8s. Target take 15% less damage per additional target. | P9: Skill Damage Factor: 500/600/700/850/1000 | Q9: 1
A10: Heart of Kamasi | B10: Marksman Unit DEF | C10: 5 | D10: 40 | E10: Legion DEF | F10: 4 | G10: 22 | H10: legendary | I10: Marksman | J10: PvP | K10: Support | L10: 1m30 | M10: 1200 | N10: Earthen Judgment | O10: Grants your Legion and 2 nearby friendly Legions: 1) Physical Keen: Physical ATK +15% 2) Onslaught: normal attack damage dealt +15% Duration: 10s Only takes effect when leading a Marksman Legion. | P10: Physical ATK bonus: 15%/18%/22%/26%/30% Normal attack damage bonus: 15%/18%/22%/26%/30% | Q10: 1
A11: Wolf-Woman of Haelor | B11: Cavalry Unit HP | C11: 5 | D11: 38 | E11: Legion HP | F11: 4 | G11: 17 | H11: legendary | I11: Cavalry | J11: Mobility | K11: / | L11: 1m30 | M11: 0 | N11: Wolfshadow | O11: Select an empty area within range to teleport your Legion to that location. 15s later, or when the Skill is recast, your Legion will return to its original location. The first enemy Legion that your Legion attacked after the Skill was cast takes additional damage. Range: 18 Damage: 15% of damage dealt to that Legion after the Skill was cast | P11: Range: 18/21/24/27/30 Additional Damage Factor: 15%/18%/21%/25%/30% | Q11: 1
A12: Shadowblades | B12: Marksman Unit ATK | C12: 5 | D12: 40 | E12: Legion ATK | F12: 4 | G12: 22 | H12: legendary | I12: Marksman | J12: PvP | K12: Assault | L12: 1m30 | M12: 1200 | N12: Shadow Games | O12: Deals damage to up to 5 enemy Legions in a designated rectangle. Damage Type: Artifact Skill Damage (Physical) Damage Factor: 1800 Target take 15% less damage per additional target. | P12: Skill Damage Factor: 1800/2200/2600/3000/3600 | Q12: 1
A13: Springs of Silence | B13: Infantry Unit ATK | C13: 5 | D13: 40 | E13: Legion ATK | F13: 4 | G13: 22 | H13: legendary | I13: Infantry | J13: PvP | K13: Control | L13: 1m30 | M13: 400 | N13: Fleeting Beauty | O13: Deals diffused damage to up to 3 enemy Legions in a designated arc. Damage Type: Physical Damage Factor: 1600 Damaged targets are Slowed: March Speed -60% for 10s. | P13: Skill Damage Factor: 1600/2000/2400/2800/3200 | Q13: 1
A14: Lucia's Horn | B14: Overall Gather Speed | C14: 8 | D14: 26 | E14: Legion DEF | F14: 4 | G14: 22 | H14: legendary | I14: Gathering | J14: / | K14: / | L14: 2h | M14: 0 | N14: Bounty of Nature | O14: After a short charge-up, a random Resource Point located in Alliance territory near your Legion. Resource Point Minimum Level: 4 Resource Point Maximum Level: 5. Charge-up cannot be interrupted.. | P14: Resource Point minimum Level: 4/4/5/6/7 Resource Point max Level: 5/6/6/7/7 | Q14: 1
A15: Breath of the Forest | B15: Garrisoned Army ATK | C15: 5 | D15: 40 | E15: Legion DEF | F15: 4 | G15: 22 | H15: legendary | I15: Garrison | J15: Support | K15: / | L15: 0 | M15: 0 | N15: Deepwood Symphony | O15: When you are Garrison Captain of a City or Stronghold, randomly grants your Legion one of the following effects every 30s while in battle. Ode: Heals once every 2s. Healing Factor: 300 Healing Duration: 10s Hymn: Grand Vigor for 10s. Effect: HP +15% Aria: Removes one debuff every 2s. Duration: 6s | P15: Healing Factor: 300/370/440/520/600 HP Bonus: 15%/18%/22%/26%/30% | Q15: 1
A16: Infernal Flame | B16: Magic Unit ATK | C16: 5 | D16: 40 | E16: Legion ATK | F16: 4 | G16: 22 | H16: legendary | I16: Magic | J16: PvP | K16: Assault | L16: 1m30 | M16: 1600 | N16: Terrifying Inferno | O16: When cast, your Legion deals additional damage whenever they launch a normal attack. Damage Type: Artifact Skill Damage (Magic) Damage Factor: 1100 Effect Duration: 3s Passive: Your Legion gains Magic Keen when the wielder inflicts Scorch on enemies. Magic Keen: ATK +15% for 5s This effect can be triggered once every 10s. | P16: Additional Magic Skill Damage Factor: 1100/1350/1600/1900/2200 Magic ATK bonus: 15%/18%/21%/25%/30% | Q16: 2
A17: Kingslayer | B17: Cavalry Unit ATK | C17: 5 | D17: 40 | E17: Legion ATK | F17: 4 | G17: 22 | H17: legendary | I17: Cavalry | J17: PvP | K17: Assault | L17: 1m30 | M17: 600 | N17: Royal Punishment | O17: Deals damage to up to 5 enemy Lgions in a designated arc. Damage Type: Artifact Skill Damage (Physical) Damage Factor: 1800 Targets take 15% less damage per additional target. If the target is another Lord's Legion and has fewer than 10% units remaining, it is immediately defeated. | P17: Skill Damage Factor: 1800/2200/2600/3000/3600 | Q17: 1
A18: Springbird Feather | B18: Legion March Speed | C18: 7.5 | D18: 37.5 | E18: Legion HP | F18: 4 | G18: 17 | H18: legendary | I18: Mobility | J18: / | K18: / | L18: 1m30 | M18: 0 | N18: Mighty Tailwind | O18: Grants your Legion and 10 surrounding friendly Legions Haste for 10s. Your Legion: March Speed +24% Friendly Legions: March Speed +16% | P18: Legion March Speed bonus: 24%/30%/36%/42%/48% Friendly Legion March Speed bonus: 16%/20%/24%/28%/32% | Q18: 1
A19: Storm Arrows | B19: Cavalry Unit ATK | C19: 5 | D19: 40 | E19: Legion ATK | F19: 4 | G19: 22 | H19: legendary | I19: Cavalry | J19: Mobility | K19: / | L19: 1m30 | M19: 0 | N19: Blink | O19: Immediately teleports your Legion to a designated empty area. Teleport Range: 15 Your Legion gains Rampage: damage dealth +12% for 4s. | P19: Range: 15/18/21/25/30 Damage bonus: 12%/15%/18%/21%/24% | Q19: 1
A20: Visage of the Sanctus | B20: Flying Unit DEF | C20: 5 | D20: 40 | E20: Legion ATK | F20: 4 | G20: 22 | H20: legendary | I20: Flying | J20: PvP | K20: Tank | L20: 1m30 | M20: 600 | N20: Strike of the Light | O20: Consecutively grants 3 Boon Shields to a selected friendly Legion. Boon Shield Factor: 900 each time Boon Shield Duration: 10s Passive: Grants 1 stack of Mark of Judgment to the wielder when they grant a shield to themselves or any friendly Legion. Mark of Judgment: Stacks up to 10 times. Casting a Rage Skill triggers Supreme Judgment and clears all Mark of Judgment stacks. Supreme Judgment: Deals damage to the target Legion. Damage Type: Artifact Skill Damage Damage Factor 250 per stack Mark of Jugdgment stacks a cleared after battle ends. | P20: Boon Shield Factor: 900/1100/1300/1550/1800 Damage Factor: 250/310/370/430/500 | Q20: 2
A21: Staff of the Prophet | B21: Magic Unit HP | C21: 5 | D21: 33 | E21: Legion HP | F21: 4 | G21: 17 | H21: legendary | I21: Magic | J21: Mobility | K21: / | L21: 8h | M21: 0 | N21: Toward the Light | O21: Select a friendly Legion within the current Region. After a 6s charge-up, your Legion and 5 nearby friendly Legions are teleported to the target's location. Your Legions will be prioritized for teleportation ahead of any other friendly Legions.If the target is within Alliance territory, cooldown is greatly reduced. | P21: Cooldown (hours): 7/6/5/4/3 | Q21: 1
A22: Dragonscale Armor | B22: Infantry Unit HP | C22: 5 | D22: 33 | E22: Legion HP | F22: 4 | G22: 17 | H22: legendary | I22: Infantry | J22: PvP | K22: Tank | L22: 1m30 | M22: 400 | N22: Entangling Flames | O22: Grants a Boon Shield to your Legion. Grants Keen to up to 3 friendly Legions in a designated circle. Boon Shield Factor: 2200 Boon Shield Duration: 10s Keen: ATK +10% for 10s Passive: Your Legion gains Ranged Resistance when the wielder gains a shield through Rage Skills. Ranged Resistance: Ranged Damage taken -9% for 5s | P22: Shield Factor: 2200/2700/3300/3900/4500 Damage Taken From Ranged Unit Reduction: 9%/11%/13%/15%/18% | Q22: 2
A23: Rattle-Spear | B23: Marksman Unit ATK | C23: 5 | D23: 40 | E23: Legion ATK | F23: 4 | G23: 22 | H23: legendary | I23: Marksman | J23: PvP | K23: Assault | L23: 1m30 | M23: 1200 | N23: Vicious Strike | O23: Strikes three times in a designated arc. The first strike has a short charge-up. The direction of subsequent strikes can change depending on the target's location.. Damage Type: Artifact Skill Damage (Physical) Damage Factor: 1200 Inflicts Slow: March Speed -20% for 3s. Additional Effect: When your Legion inflicts DEF Break on an enemy Legion, your Legion gains DEF Penetration: ignore 10% of the enemy's DEF for 7s. | P23: Skill Damage Factor: 1200/1500/1800/2100/2500 DEF Penetration: 10%/12%/14%/17%/20% | Q23: 2
A24: Cloak of Stealth | B24: Cavalry Unit ATK | C24: 3 | D24: 28 | E24: Legion ATK | F24: 3 | G24: 18 | H24: epic | I24: Cavalry | J24: Mobility | K24: / | L24: 1h | M24: 0 | N24: Subterfuge | O24: Grants your Legions Stealth: March Speed -15% for 300s. While in Stealth, Legions can only be detected if they move too close to the enemy. Launching attacks, taking damage, or opening Chests will cause Stealth to expire. | P24: Duration: 300/600/900/1300/1800 March Speed reduction: 25%/25%/25%/25%/15% | Q24: 1
A25: Heartpiercer | B25: Marksman Unit ATK | C25: 3 | D25: 28 | E25: Legion ATK | F25: 3 | G25: 18 | H25: epic | I25: Marksman | J25: PvP | K25: Assault | L25: 1m30 | M25: 1200 | N25: Heart Shot | O25: Deals damage to the selected Legion. Damage Type: Artifact Skill Damage (Physical) Damage Factor: 1000 Target has 40% chance to gain Physical DEF Break: Physical DEF -15% for 3s. | P25: Skill Damage Factor: 1000/1200/1400/1700/2000 Probability: 40%/45%/50%/55%/65% | Q25: 1
A26: Bomb Flinger | B26: Marksman Unit ATK | C26: 3 | D26: 28 | E26: Legion ATK | F26: 3 | G26: 18 | H26: epic | I26: Marksman | J26: Peacekeeping | K26: / | L26: 1m30 | M26: 0 | N26: Bomb Away | O26: Deals damage to the selected Legion (Darklings, Dark Creatures, and Behemoths only). Damage Type: Artifact Skill Damage (Physical) Damage Factor: 1200 Damaged targets have a 40% chance to be Stunned: cannot move or act for 2s. | P26: Skill Damage Factor: 1200/1500/1800/2100/2400 Probability: 40%/50%/60%/70%/80% | Q26: 1
A27: Enchiridion of Advanced Incantations | B27: Magic Unit ATK | C27: 3 | D27: 28 | E27: Legion ATK | F27: 3 | G27: 18 | H27: epic | I27: Magic | J27: Peacekeeping | K27: / | L27: 1m30 | M27: 0 | N27: Fireburst | O27: Deals damage to the selected Legion (Darklings, Dark Creatures, and Behemoths only). Damage Type: Artifact Skill Damage (Magic) Damage Factor:1400 | P27: Skill Damage Factor: 1400/1700/2000/2400/2800 | Q27: 1
... A69: Lunaris | B69: Cavalry Unit ATK | C69: 5 | D69: 40 | E69: Legion ATK | F69: 4 | G69: 22 | H69: legendary | I69: Cavalry | J69: PvP | K69: Assault | L69: 1m30 | M69: 600 | N69: Moon's Judgment | O69: Deals diffused damage to up to 3 enemy Legions in a designated cone. Grants the Legion Rampage and Resistance for 10s. Rampage: Damage dealt +7% Resistance: Damage taken -5% Damage Type: Physical Damage Factor: 2200 Additional Effect Legion gains Haste while Camouflaged, and gains Synergy when the Camouflaged status is removed. Haste: March Speed +20% Synergy: Hero Skill damage +10% for 15s. | P69: Skill Damage Factor: 2200/2750/3300/3850/4400 Damage deault bonus: 7%/9%/11%/13%/15% Damage taken reduction: 5%/6%/7%/8%/10% March Speed bonus: 20%/25%/30%/35%/40% Hero Skill damage deault bonus: 10%/12%/14%/17%20% | Q69: 4
A70: Serpent's Edge | B70: Infantry Unit ATK | C70: 5 | D70: 40 | E70: Legion DEF | F70: 4 | G70: 22 | H70: legendary | I70: Infantry | J70: PvP | K70: Tank | L70: 1m30 | M70: 400 | N70: Bloodbite | O70: For the next 20s, the Legion gains 30% HP, and deals diffused Physical damage to up to 3 nearby enemy Legions every 3s (Damage Factor 400). Targets gain Slow: March Speed -10% for 3s. Additional Effect When gaining an HP buff via a Hero Skill, the Legion gains 10% ATK and DEF for 5s (max 5 stacks). | Q70: 4

Sheet Research
A1: No motivation atm

Sheet Main quests
A1: Same

Sheet Hero Token Cost
A1: # of upgrade | B1: Legendary | C1: Total Leg | D1: Epic | E1: Rare | F1: 1/1/1/1 | G1: 4 Upgrades per Skill
A2: 1 | B2: 10 | C2: =sum(B$2:B2) -> 10 | D2: 10 | E2: 10
A3: 2 | B3: 10 | C3: =sum(B$2:B3) -> 20 | D3: 10 | E3: 10
A4: 3 | B4: 15 | C4: =sum(B$2:B4) -> 35 | D4: 10 | E4: 10
A5: 4 | B5: 15 | C5: =sum(B$2:B5) -> 50 | D5: 20 | E5: 10 | F5: 5/1/1/1
A6: 5 | B6: 30 | C6: =sum(B$2:B6) -> 80 | D6: 20 | E6: 10
A7: 6 | B7: 30 | C7: =sum(B$2:B7) -> 110 | D7: 20 | E7: 20
A8: 7 | B8: 40 | C8: =sum(B$2:B8) -> 150 | D8: 20 | E8: 20
A9: 8 | B9: 40 | C9: =sum(B$2:B9) -> 190 | D9: 30 | E9: 20 | F9: 5/5/1/1
A10: 9 | B10: 45 | C10: =sum(B$2:B10) -> 235 | D10: 30 | E10: 20
A11: 10 | B11: 45 | C11: =sum(B$2:B11) -> 280 | D11: 30 | E11: 20
A12: 11 | B12: 50 | C12: =sum(B$2:B12) -> 330 | D12: 30 | E12: 30
A13: 12 | B13: 50 | C13: =sum(B$2:B13) -> 380 | D13: 40 | E13: 30 | F13: 5/5/5/1
A14: 13 | B14: 75 | C14: =sum(B$2:B14) -> 455 | D14: 40 | E14: 30
A15: 14 | B15: 75 | C15: =sum(B$2:B15) -> 530 | D15: 40 | E15: 30
A16: 15 | B16: 80 | C16: =sum(B$2:B16) -> 610 | D16: 40 | E16: 30
A17: 16 | B17: 80 | C17: =sum(B$2:B17) -> 690 | D17: 50 | E17: 40 | F17: 5/5/5/5
A18: Total | B18: =sum(B2:B17) -> 690 | D18: =sum(D2:D17) -> 440 | E18: =sum(E2:E17) -> 340
A21: 235+
A23: 5 | B23: 4364 | D23: =A23*B23 -> 21820
A24: 10 | B24: 6777 | D24: =A24*B24 -> 67770
A25: 50 | B25: 1774 | D25: =A25*B25 -> 88700
A26: 100 | B26: 521 | D26: =A26*B26 -> 52100
A27: 200 | B27: 165 | D27: =A27*B27 -> 33000
A28: 500 | B28: 153 | D28: =A28*B28 -> 76500
A29: 1000 | B29: 102 | D29: =A29*B29 -> 102000
D30: =SUM(D23:D29) -> 441890
A34: 5 | B34: 2104 | C34: =A34*B34 -> 10520 | H34: Damage: | I34: Stats: | K34: Inf: 15 CA
A35: 10 | B35: 5763 | C35: =A35*B35 -> 57630 | H35: 1000 x3 (Diffused) | I35: 10 ATK | K35: Cav: 6 DMG Flat
A36: 50 | B36: 1571 | C36: =A36*B36 -> 78550 | H36: 30 Rage | I36: 20 March Speed | K36: MM: 20 NA DMG
A37: 100 | B37: 449 | C37: =A37*B37 -> 44900 | I37: 20 DEF (merge with ATK Resistance) | K37: Mage: 10 DMG Res
A38: 200 | B38: 155 | C38: =A38*B38 -> 31000
A39: 500 | B39: 134 | C39: =A39*B39 -> 67000 | H39: 300 Damage every 15s
A40: 1000 | B40: 92 | C40: =A40*B40 -> 92000
C41: =SUM(C34:C40) -> 381600
H42: Daily | I42: 1200 | J42: 3.49 | K42: 2 | L42: =I42*K42 -> 2400 | M42: =J42*K42 -> 6.98
A43: 1000 | B43: 305 | C43: =A43*B43 -> 305000 | H43: Monthly 1 | I43: 750 | J43: 3.49 | K43: 2 | L43: =I43*K43 -> 1500 | M43: =J43*K43 -> 6.98
A44: 5000 | B44: 31 | C44: =A44*B44 -> 155000 | H44: Monthly 2 | I44: 1500 | J44: 5.99 | K44: 1 | L44: =I44*K44 -> 1500 | M44: =J44*K44 -> 5.99
A45: 20000 | B45: 63 | C45: =A45*B45 -> 1260000
A46: 50000 | B46: 34 | C46: =A46*B46 -> 1700000
...

Sheet Talent Tree
A1: ID | B1: Tree | C1: NodeID | D1: Requirement
A2: -3.1 | B2: Foundation Talents | C2: 1 | E2: =VLOOKUP(C2,'Talent Node'!A:E,2,FALSE) -> Overall Attack
A3: -2.2 | B3: Foundation Talents | C3: 2 | E3: =VLOOKUP(C3,'Talent Node'!A:E,2,FALSE) -> Overall Speed
A4: -2.1 | B4: Foundation Talents | C4: 3 | E4: =VLOOKUP(C4,'Talent Node'!A:E,2,FALSE) -> Overall Defense
A5: -1.3 | B5: Foundation Talents | C5: 5 | E5: =VLOOKUP(C5,'Talent Node'!A:E,2,FALSE) -> Logistics Master
A6: -1.2 | B6: Foundation Talents | C6: 4 | E6: =VLOOKUP(C6,'Talent Node'!A:E,2,FALSE) -> Overall Health
A7: -1.1 | B7: Foundation Talents | C7: 27 | E7: =VLOOKUP(C7,'Talent Node'!A:E,2,FALSE) -> Bane of Darkness
A8: 1.1 | B8: Marksman | C8: 13 | E8: =VLOOKUP(C8,'Talent Node'!A:E,2,FALSE) -> Marksman ATK
A9: 2.1 | B9: Marksman | C9: 15 | E9: =VLOOKUP(C9,'Talent Node'!A:E,2,FALSE) -> Marksman Speed
A10: 2.2 | B10: Marksman | C10: 14 | E10: =VLOOKUP(C10,'Talent Node'!A:E,2,FALSE) -> Fully Loaded
A11: 2.3 | B11: Marksman | C11: 11 | E11: =VLOOKUP(C11,'Talent Node'!A:E,2,FALSE) -> Head Held High
A12: 3.1 | B12: Marksman | C12: 18 | E12: =VLOOKUP(C12,'Talent Node'!A:E,2,FALSE) -> Alert
A13: 3.2 | B13: Marksman | C13: 17 | E13: =VLOOKUP(C13,'Talent Node'!A:E,2,FALSE) -> Steady Shot
A14: 3.3 | B14: Marksman | C14: 16 | E14: =VLOOKUP(C14,'Talent Node'!A:E,2,FALSE) -> Intimidation
A15: 4.1 | B15: Marksman | C15: 20 | E15: =VLOOKUP(C15,'Talent Node'!A:E,2,FALSE) -> Shower of Blows
A16: 4.2 | B16: Marksman | C16: 19 | E16: =VLOOKUP(C16,'Talent Node'!A:E,2,FALSE) -> Bullseye
A17: 5.1 | B17: Marksman | C17: 22 | E17: =VLOOKUP(C17,'Talent Node'!A:E,2,FALSE) -> Marksman HP
A18: 5.2 | B18: Marksman | C18: 23 | E18: =VLOOKUP(C18,'Talent Node'!A:E,2,FALSE) -> Magic Countertactics
A19: 5.3 | B19: Marksman | C19: 21 | E19: =VLOOKUP(C19,'Talent Node'!A:E,2,FALSE) -> Egoism
A20: 6.1 | B20: Marksman | C20: 26 | D20: 5.1 | E20: =VLOOKUP(C20,'Talent Node'!A:E,2,FALSE) -> Delight
A21: 6.2 | B21: Marksman | C21: 25 | E21: =VLOOKUP(C21,'Talent Node'!A:E,2,FALSE) -> Binding Snare
A22: 6.3 | B22: Marksman | C22: 24 | E22: =VLOOKUP(C22,'Talent Node'!A:E,2,FALSE) -> Callousness
A23: 7.1 | B23: Marksman | C23: 35 | E23: =VLOOKUP(C23,'Talent Node'!A:E,2,FALSE) -> Last Word
A24: 7.2 | B24: Marksman | C24: 56 | E24: =VLOOKUP(C24,'Talent Node'!A:E,2,FALSE) -> Radical
A25: 7.3 | B25: Marksman | C25: 57 | E25: =VLOOKUP(C25,'Talent Node'!A:E,2,FALSE) -> Harvest
A26: 8.1 | B26: Marksman | C26: 29 | E26: =VLOOKUP(C26,'Talent Node'!A:E,2,FALSE) -> Pursuit
A27: 8.2 | B27: Marksman | C27: 28 | E27: =VLOOKUP(C27,'Talent Node'!A:E,2,FALSE) -> Burst Shot
A28: 1.1 | B28: Rally | C28: 9 | E28: =VLOOKUP(C28,'Talent Node'!A:E,2,FALSE) -> Overall Health
A29: 2.1 | B29: Rally | C29: 8 | E29: =VLOOKUP(C29,'Talent Node'!A:E,2,FALSE) -> Overall Defense
A30: 2.2 | B30: Rally | C30: 6 | E30: =VLOOKUP(C30,'Talent Node'!A:E,2,FALSE) -> Overall Attack
A31: 2.3 | B31: Rally | C31: 7 | E31: =VLOOKUP(C31,'Talent Node'!A:E,2,FALSE) -> Overall Speed
A32: 3.1 | B32: Rally | C32: 247 | E32: =VLOOKUP(C32,'Talent Node'!A:E,2,FALSE) -> Pincer Attack
... A43: 7.1 | B43: Rally | C43: 41 | E43: =VLOOKUP(C43,'Talent Node'!A:E,2,FALSE) -> Frontline Support
A44: 7.2 | B44: Rally | C44: 40 | D44: 6.2 | E44: =VLOOKUP(C44,'Talent Node'!A:E,2,FALSE) -> Plan of Attack
A45: 7.3 | B45: Rally | C45: 252 | E45: =VLOOKUP(C45,'Talent Node'!A:E,2,FALSE) -> Armored Assault
A46: 8.1 | B46: Rally | C46: 43 | E46: =VLOOKUP(C46,'Talent Node'!A:E,2,FALSE) -> Reversal of Fortune
A47: 8.2 | B47: Rally | C47: 42 | E47: =VLOOKUP(C47,'Talent Node'!A:E,2,FALSE) -> Trailblazer
A48: 0 | B48: Precision | C48: 12 | E48: =VLOOKUP(C48,'Talent Node'!A:E,2,FALSE) -> Arrow of Precision
A49: 1.1 | B49: Precision | C49: 6 | E49: =VLOOKUP(C49,'Talent Node'!A:E,2,FALSE) -> Overall Attack
A50: 2.1 | B50: Precision | C50: 7 | E50: =VLOOKUP(C50,'Talent Node'!A:E,2,FALSE) -> Overall Speed
...

Sheet Talent Node
A1: ID | B1: Name | C1: Max Rank | D1: Description | E1: Node Type | F1: Image | G1: Value 1 | H1: Value 2 | I1: Value 3 | J1: Value 4 | K1: Value 5 | L1: Bonus
A2: 1 | B2: Overall Attack | C2: 3 | D2: Increases the ATK of your Legion's units by {value}%. | E2: node | F2: attack | G2: 0.4 | H2: 0.8 | I2: 1.2 | L2: STATS_ATK
A3: 2 | B3: Overall Speed | C3: 3 | D3: Increases the March Speed of your Legion's unit by {value}%. | E3: node | F3: speed | G3: 2 | H3: 4 | I3: 6 | L3: STATS_MS
A4: 3 | B4: Overall Defense | C4: 3 | D4: Increases the DEF of your Legion's unit by {value}%. | E4: node | F4: defense | G4: 0.4 | H4: 0.8 | I4: 1.2 | L4: STATS_DEF
A5: 4 | B5: Overall Health | C5: 3 | D5: Increases the HP of your Legion's unit by {value}%. | E5: node | F5: hp | G5: 0.4 | H5: 0.8 | I5: 1.2 | L5: STATS_HP
A6: 5 | B6: Logistics Master | C6: 3 | D6: Increases your Legion's Gather Speed by {value}%. | E6: node | F6: gather | G6: 3 | H6: 6 | I6: 9 | L6: GATHERINGSTATS_GATHER
A7: 6 | B7: Overall Attack | C7: 5 | D7: Increases the ATK of your Legion's units by {value}%. | E7: node | F7: attack | G7: 0.4 | H7: 0.8 | I7: 1.2 | J7: 1.6 | K7: 2 | L7: STATS_ATK
A8: 7 | B8: Overall Speed | C8: 5 | D8: Increases the March Speed of your Legion's unit by {value}%. | E8: node | F8: speed | G8: 2 | H8: 4 | I8: 6 | J8: 8 | K8: 10 | L8: STATS_MS
A9: 8 | B9: Overall Defense | C9: 5 | D9: Increases the DEF of your Legion's unit by {value}%. | E9: node | F9: defense | G9: 0.4 | H9: 0.8 | I9: 1.2 | J9: 1.6 | K9: 2 | L9: STATS_DEF
A10: 9 | B10: Overall Health | C10: 5 | D10: Increases the HP of your Legion's unit by {value}%. | E10: node | F10: hp | G10: 0.4 | H10: 0.8 | I10: 1.2 | J10: 1.6 | K10: 2 | L10: STATS_HP | O10: (archer)
A11: 10 | B11: Logistics Master | C11: 5 | D11: Increases your Legion's Gather Speed by {value}%. | E11: node | F11: gather | G11: 3 | H11: 6 | I11: 9 | J11: 12 | K11: 15 | L11: GATHERINGSTATS_GATHER | O11: (mage)
A12: 11 | B12: Head Held High | C12: 5 | D12: Launching a normal attack has a 10% chance to grant your Legion {value} Rage. | E12: node | F12: rage | G12: 10 | H12: 20 | I12: 30 | J12: 40 | K12: 50 | L12: NA_RAGE | O12: (cavalry)
A13: 12 | B13: Arrow of Precision | C13: 1 | D13: Your Legion deals 2% more normal attack damage, and ignores 1% of the enemy's DEF while in battle. | E13: main_node | F13: def_break | L13: STATS_ARROW_OF_PRECISION | O13: (infantry)
A14: 13 | B14: Marksman ATK | C14: 5 | D14: Increases the ATK of your Legion's Marksman units by {value}%. | E14: node | F14: attack | G14: 0.5 | H14: 1 | I14: 1.5 | J14: 2 | K14: 2.5 | L14: STATS_ATK(archer)
A15: 14 | B15: Fully Loaded | C15: 5 | D15: Your Legion deals {value}% more normal attack damage when launching ranged attacks. | E15: node | F15: normal_attack | G15: 1 | H15: 2 | I15: 3 | J15: 4 | K15: 5 | L15: STATS_NA | N15: Trigger
A16: 15 | B16: Marksman Speed | C16: 5 | D16: Increases the March Speed of your Legion's Marksman unit by {value}%. | E16: node | F16: speed | G16: 3 | H16: 6 | I16: 9 | J16: 12 | K16: 15 | L16: STATS_MS(archer) | N16: STATS_ | O16: Raw Stats
A17: 16 | B17: Intimidation | C17: 5 | D17: Your Legion deals {value}% more Hero Skill damage. | E17: node | F17: intimidation | G17: 0.8 | H17: 1.6 | I17: 2.4 | J17: 3.2 | K17: 4 | L17: STATS_HS | N17: RS_ | O17: On Rage Skill
A18: 17 | B18: Steady Shot | C18: 5 | D18: Reduces the Attack Range of your Legion's Marksman units by 3, but increases their ATK by {value}%. | E18: node | F18: attack | G18: 3 | H18: 3.5 | I18: 4 | J18: 4.5 | K18: 5 | L18: STATS_STEADY_SHOT | N18: NA_ | O18: On Normal Attack
A19: 18 | B19: Alert | C19: 5 | D19: Your Legion takes {value}% less damage. | E19: node | F19: angel | G19: 0.3 | H19: 0.6 | I19: 0.9 | J19: 1.2 | K19: 1.5 | L19: STATS_RES | N19: BATTLE_ | O19: When in battle, get x every x
A20: 19 | B20: Bullseye | C20: 1 | D20: When your Legion consists entirely of Marksman units, they gain 5 stacks of ATK Increase every 10s while in battle. Each stack increases their ATK by 1%. Each normal attack they launch removes 1 stack. | E20: major_node | F20: bullseye | G20: 1.5 | L20: BATTLE_BULLEYE | N20: ARTIFACT_ | O20: On Artifacts Skill
A21: 20 | B21: Shower of Blows | C21: 1 | D21: When casting Rage Skills, there is a 50% chance that your next Rage Skill will deal 8% more damage. | E21: major_node | F21: intimidation | G21: 4 | L21: RS_SHOWER_OF_BLOWS | N21: OVER_ | O21: Unit Over
A22: 21 | B22: Egoism | C22: 5 | D22: Your Legion takes {value}% less Hero Skill damage. | E22: node | F22: hs_def | G22: 0.8 | H22: 1.6 | I22: 2.4 | J22: 3.2 | K22: 4 | L22: STATS_HS_RES | N22: LOWER_ | O22: Unit Lower
A23: 22 | B23: Marksman HP | C23: 5 | D23: Increases the HP of your Legion's Marksman units by {value}%. | E23: node | F23: hp | G23: 0.5 | H23: 1 | I23: 1.5 | J23: 2 | K23: 2.5 | L23: STATS_HP(archer) | N23: OTHER_ | O23: Like getting chest on gathering node or idk
A24: 23 | B24: Magic Countertactics | C24: 5 | D24: Your Legion's Marksman units deal {value}% more damage to Magic units. | E24: node | F24: magic_counterattack | G24: 1 | H24: 2 | I24: 3 | J24: 4 | K24: 5 | L24: STATS_DAMAGE_TO_MAGIC(archer) | N24: DEFEATING_ | O24: On defeating legion
A25: 24 | B25: Callousness | C25: 5 | D25: When your Legion's Unit Count is below 50%, their ATK increases by {value}%. | E25: node | F25: callousness | G25: 0.5 | H25: 1 | I25: 1.5 | J25: 2 | K25: 2.5 | L25: LOWER_ATK | N25: DEBUFFAPPLIED_ | O25: On debuff applied/inflicts
A26: 25 | B26: Binding Snare | C26: 5 | D26: When your Legion is hit with a normal attack, they have 10% chance to Slow the target Legion, reducing their March Speed by {value}% for 5s. | E26: node | F26: slow_speed | G26: 4 | H26: 8 | I26: 12 | J26: 16 | K26: 20 | L26: HIT_BINDING_SNARE | N26: DEBUFFRECEIVED_ | O26: On debuff received
A27: 26 | B27: Delight | C27: 5 | D27: Increases Rage Accumulation Speed by {value}% when your Legion's Unit Count is over 50%. | E27: node | F27: rage | G27: 5 | H27: 6 | I27: 9 | J27: 12 | K27: 15 | L27: OVER_RAGE | N27: HEALING_ | O27: On shield or healing received
A28: 27 | B28: Bane of Darkness | C28: 3 | D28: Your Legion deals {value}% more Peacekeeping damage. | E28: node | F28: peacekeeping | G28: 1 | H28: 2 | I28: 3 | L28: PEACEKEEPING_PK_DMG | N28: HIT_ | O28: When hit by Normal Attack
A29: 28 | B29: Burst Shot | C29: 1 | D29: When your Marksman Legion launches a normal attack, they deal additional damage. Damage Type: Physical Damage Factor: 150 This effect can be triggered once every 10s. | E29: major_node | F29: furious | L29: NA_BURST_SHOT | N29: UNIT_ | O29: Legion Size
A30: 29 | B30: Pursuit | C30: 1 | D30: When your Legion consists entirely of Marksman units, they inflict Fragility when casting Rage Skills, increasing normal attack damage taken by 10% for 5s. This effect can be triggered once every 10s. | E30: major_node | F30: def_break | L30: RS_PURSUIT | N30: DMG_ | O30: Damage
A31: 30 | B31: Arson | C31: 5 | D31: When your Legion defeats an enemy Garrisoned Army, the time the City or Stronghold burns for is increased by {value}%. | E31: node | F31: arson | G31: 4 | H31: 8 | I31: 12 | J31: 16 | K31: 20 | L31: OTHER_ARSON | N31: START_ | O31: At start of battle
A32: 31 | B32: Adrenaline Rush | C32: 5 | D32: Your Legion deal {value}% more normal attack damage. | E32: node | F32: normal_attack | G32: 0.8 | H32: 1.6 | I32: 2.4 | J32: 3.2 | K32: 4 | L32: STATS_NA | N32: DEFPEN_ | O32: Defense Penetration
A33: 32 | B33: Watch This | C33: 5 | D33: Increases damage dealt to Watch Towers by {value}%. | E33: node | F33: watch | G33: 5 | H33: 10 | I33: 15 | J33: 20 | K33: 25 | L33: OTHER_WATCH_THIS | N33: HPPEN_ | O33: HP Bypass
A34: 33 | B34: Fair Offense | C34: 1 | D34: While serving as Rally Captain, you can force the enemy Rallied Army or Garrisoned Army into a Fair Fight. In a Fair Fight, all Unit Skills are disabled, and the attributes of Infantry, Cavalry, Marksman, and Magic units of the same level will be adjusted to the same values. | E34: major_node | F34: trophy | L34: RALLY_FAIR_OFFENSE | N34: HSHIT_ | O34: When hit by Rage Skill
A35: 34 | B35: Landslide | C35: 1 | D35: When your Legion's Unit Count is over 50%, units deal 3% more damage. | E35: major_node | F35: landslide | L35: OVER_LANDSLIDE
A36: 35 | B36: Last Word | C36: 5 | D36: Your Legion deals {value}% more counterattack damage. | E36: node | F36: counterattack | G36: 0.8 | H36: 1.6 | I36: 2.4 | J36: 3.2 | K36: 4 | L36: STATS_CA
A37: 36 | B37: Steel Monsoon | C37: 5 | D37: Increases March Speed by {value}% for 10s when your Rallied Army leaves a building after launching a Rally. | E37: node | F37: haste | G37: 8 | H37: 16 | I37: 24 | J37: 32 | K37: 40 | L37: RALLY_STEEL_MONSOON
A38: 37 | B38: Frustration | C38: 5 | D38: When your Legion launches a normal attack, they have a 10% chance to reduce the target's healing and shield received by {value}% for 5s. This effect can be triggered once every 5s. | E38: node | F38: blessing | G38: 1 | H38: 2 | I38: 3 | J38: 4 | K38: 5 | L38: NA_FRUSTRATION
A39: 38 | B39: Flank Protection | C39: 5 | D39: Your Legion takes {value}% less bonus damage from being Surrounded. | E39: node | F39: arson | G39: 15 | H39: 30 | I39: 45 | J39: 60 | K39: 75 | L39: STATS_FLANK_PROTECTION
A40: 39 | B40: War Banner | C40: 5 | D40: Increases maximum Legion Capacity by {value}. | E40: node | F40: arson | G40: 300 | H40: 600 | I40: 900 | J40: 1200 | K40: 1500 | L40: STATS_UNIT
...

Sheet Hero
A1: Name | B1: Title | C1: Quality | D1: Category 1 | E1: Category 2 | F1: Category 3 | G1: Season | H1: Flying
A2: Ordo | B2: One-Eyed Veteran | C2: rare | D2: Overall | E2: Engineering | F2: Tank | G2: 1 | H2: FALSE
A3: Chakcha | B3: Gourmet Hunter | C3: rare | D3: Overall | E3: Gather | F3: Skills | G3: 1 | H3: FALSE
A4: Kella | B4: Savvy Trader | C4: rare | D4: Overall | E4: Gather | F4: Support | G4: 1 | H4: FALSE
A5: Pan | B5: Dream Herald | C5: epic | D5: Overall | E5: Gather | F5: Support | G5: 1 | H5: FALSE
A6: Atheus | B6: Auspex | C6: epic | D6: Magic | E6: PvP | F6: Mobility | G6: 1 | H6: TRUE
A7: Waldyr | B7: Ice Mage | C7: epic | D7: Magic | E7: PvP | F7: Skills | G7: 1 | H7: FALSE
A8: Gwanwyn | B8: Arrow of the Wind | C8: epic | D8: Marksman | E8: Peacekeeping | F8: Precision | G8: 1 | H8: FALSE
A9: Kregg | B9: Mad Bomber | C9: epic | D9: Marksman | E9: Engineering | F9: Mobility | G9: 1 | H9: TRUE
A10: Alistair | B10: Royal Court Guard | C10: epic | D10: Cavalry | E10: Rally | F10: Tank | G10: 1 | H10: FALSE
A11: Alwyn | B11: Master of Poisons | C11: epic | D11: Magic | E11: PvP | F11: Control | G11: 1 | H11: FALSE
A12: Bakhar | B12: Unyielding Blade | C12: epic | D12: Infantry | E12: Garrison | F12: Skills | G12: 1 | H12: FALSE
A13: Eliana | B13: Daughter of Dawn | C13: epic | D13: Overall | E13: Peacekeeping | F13: Support | G13: 1 | H13: FALSE
... A52: Lei Kuan | B52: Thunder God | C52: legendary | D52: Infantry | E52: Rally | F52: Tank | G52: 4 | H52: FALSE

Sheet Hero Skills
A1: Hero | B1: Name | C1: Rage Cost | D1: Description | E1: Upgrade | F1: Skill Enhanced | G1: Holistic
A2: Ordo | B2: Unbreakable Barrier | C2: 1000 | D2: Legion gains a shield for 5s that absorbs a massive amount of damage (Shield Factor 400). | E2: Shield Factor 150/200/250/325/400
A3: Ordo | B3: In Full Swing | D3: All Legions: Increases Engineering by 18% when building or destroying buildings in the field. | E3: Engineering bonus 6%/9%/12%/15%/18% | G3: TRUE
A4: Ordo | B4: Clearsighted | D4: All Legions: Increases Gather Speed by 5%, Load Capacity by 5%, and Mana Gather Speed by an extra 10%. | E4: Gather Speed bonus 1%/2%/3%/4%/5% Legion Load Capacity bonus 1%/2%/3%/4%/5% Mana Gather Speed bonus 3%/4%/6%/8%/10% | G4: TRUE
A5: Ordo | B5: Seasoned | D5: Reduces all damage taken by Legion by 10%. This damage reduction is doubled while the Legion is building or destroying Infrastructure or gathering resources. | E5: Damage taken reduction 3%/4%/6%/8%/10%
A6: Bertrand | B6: Entitled Rage | C6: 1000 | D6: Bertrand deals damage to the target Legion and consumes all stacks of Golden Mark, increasing damage dealt by 5% per stack. Damage Type: Magic Damage Factor: 1300 | E6: Skill Damage Factor 700/800/900/1100/1300
A7: Bertrand | B7: Compound Interest | D7: When Legion deals Hero Skill damage, they gains 1 stack of Golden Mark for 5s (max 3 stacks). Each stack of Golden Mark increases Hero Skill damage dealt by 10%. | E7: Hero Skill damage dealt bonus 4%/5%/6%/8%/10%
A8: Bertrand | B8: Magic Circle | D8: Legion Magic units gain 25% Magic ATK and 10% DEF Penetration. | E8: Magic unit Magic ATK bonus 10%/13%/16%/20%/25% Magic unit enemy DEF penetration 4%/5%/6%/8%/10%
A9: Bertrand | B9: Blue Blood | D9: While in the field, Legion gains 15% ATK and DEF if they have not taken normal attack damage for 3s. | E9: ATK and DEF bonus 5%/7%/9%/12%/15%
A10: Bertrand | B10: Noblesse Oblige | D10: Bertrand deals damage to the target Legion and consumes all stacks of Golden Mark, increasing damage dealt by 5% per stack. Damage Type: Magic Damage Factor: 1500 | F10: Entitled Rage
A11: Tohar | B11: Earth Conduit | D11: After launching 3 normal attacks, Tohar channels Rage of the Plateau, dealing damage to the target every second for up to 3s. Damage Type: Magic Damage Factor: 500 Cooldown: 4s If a Hero in Tohar's Legion casts a Rage Skill, the cooldown ands immediatly. | E11: Skill Damage Factor 250/300/350/400/500
A12: Tohar | B12: Defensive Fortifications | D12: When garrisoning Cities or Strongholds, the Garrisoned Army gains 20% ATK. Each time Earth Conduit is cast, it has a 50% chance to hit an extra 3 enemy Legions, dealing diffused damage (Damage Factor 200). | E12: ATK bonus 10%/12%/14%/16%/20%
A13: Tohar | B13: Shamanic Mastery | D13: Legion Magic units deal 30% more Hero skill damage, but deal 5% less normal attack damage. | E13: Magic unit Hero Skill damage dealt bonus 10%/15%/20%/25%/30%
A14: Tohar | B14: Plateau Protection | D14: When channeling Rage of the Plateau, his Legion gains Unyielding and Shelter for 5s. Unyielding: Counterattack damage taken -15% Shelter: DEF +35% | E14: Counterattack damage taken reduction 5%/7%/9%/12%/15% DEF bonus 15%/20%/25%/30%/35%
A15: Tohar | B15: Earth Ritual | D15: After Tohar finishes channeling Rage of the Plateau, his Legion gains Keen: ATK +35% for 5s.
A16: Syndrion | B16: Greenfeather | C16: 1000 | D16: Legion gains Keen and Rapid-Fire, increasing their ATK by 20% and launching and additional normal attack every second for 7s. | E16: Duration 3/4/5/6/7
A17: Syndrion | B17: Soaring Ambition | D17: When besieging a City or Stronghold, Legion gains 10% ATK and ignores 5% of the enemy's DEF. | E17: ATK bonus 4%/5%/6%/8%/10% DEF Penetration 1%/2%/3%/4%/5%
A18: Syndrion | B18: Feather Strike | D18: Legion Marksman units gain 10% normal attack Crit Rate and 15% HP. | E18: Marksman unit normal attack Crit Rate bonus 4%/5%/6%/8%/10% Marksman unit HP bonus 5%/7%/9%/12%/15%
A19: Syndrion | B19: Forest Shadow | D19: When battle begins, Legion gains Rapid-Fire for 3s, launching an extra attack every time they launch a normal attack. 3s after battle begins, Legion gains 20% ATK, lasting until battle ends. | E19: ATK bonus 10%/12%/14%/16%/20% Duration 1/1/2/2/3
A20: Syndrion | B20: Free as the Wind | D20: Every time Syndrion's Legion lands 5 critical hit(s) from normal attacks, they deal additional damage to the target Legion. Damage Type: Physical Damage Factor: 400
A21: Skogul | B21: Bloodsoaked Battle | C21: 1000 | D21: Skogul's Legion gains Vigor and Bloodfury for 6s. Vigor: HP +15% Bloodfury: Legion deals additional diffused counterattack damage every second to all Legions at close range when they launch a normal attack on your Legion | E21: Duration 2/3/4/5/6 HP bonus 5%/7%/9%/12%/15%
A22: Skogul | B22: Unshakeable | D22: Legion Infantry units gain 20% Physical ATK and 10% HP. | E22: Infantry unit Physical ATK bonus 5%/8%/11%/15%/20% HP bonus 4%/5%/6%/8%/10%
